2022-07-08 08:58:42,428 - INFO: 127.0.0.1 - - [08/Jul/2022 08:58:42] "GET / HTTP/1.1" 200 -
2022-07-08 08:58:42,552 - INFO: 127.0.0.1 - - [08/Jul/2022 08:58:42] "[36mGET /static/bootstrap.min.css HTTP/1.1[0m" 304 -
2022-07-08 08:58:42,552 - INFO: 127.0.0.1 - - [08/Jul/2022 08:58:42] "[36mGET /static/style.css HTTP/1.1[0m" 304 -
2022-07-08 08:58:42,582 - INFO: 127.0.0.1 - - [08/Jul/2022 08:58:42] "[36mGET /static/jquery.min.js HTTP/1.1[0m" 304 -
2022-07-08 08:58:42,642 - INFO: 127.0.0.1 - - [08/Jul/2022 08:58:42] "[36mGET /static/toastr.min.css HTTP/1.1[0m" 304 -
2022-07-08 08:58:42,693 - INFO: 127.0.0.1 - - [08/Jul/2022 08:58:42] "[36mGET /static/assets/Sennerei_Logo.png HTTP/1.1[0m" 304 -
2022-07-08 08:58:42,694 - INFO: 127.0.0.1 - - [08/Jul/2022 08:58:42] "[36mGET /static/assets/Mack_Logo.svg HTTP/1.1[0m" 304 -
2022-07-08 08:58:42,711 - INFO: 127.0.0.1 - - [08/Jul/2022 08:58:42] "[36mGET /static/bootstrap.bundle.min.js HTTP/1.1[0m" 304 -
2022-07-08 08:58:42,803 - INFO: 127.0.0.1 - - [08/Jul/2022 08:58:42] "[36mGET /static/chart.js HTTP/1.1[0m" 304 -
2022-07-08 08:58:42,815 - INFO: 127.0.0.1 - - [08/Jul/2022 08:58:42] "[36mGET /static/chart.min.js HTTP/1.1[0m" 304 -
2022-07-08 08:58:42,815 - INFO: 127.0.0.1 - - [08/Jul/2022 08:58:42] "[36mGET /static/toastr.min.js HTTP/1.1[0m" 304 -
2022-07-08 08:58:42,858 - INFO: 127.0.0.1 - - [08/Jul/2022 08:58:42] "[36mGET /static/assets/graph-up.svg HTTP/1.1[0m" 304 -
2022-07-08 08:58:42,898 - INFO: 127.0.0.1 - - [08/Jul/2022 08:58:42] "[36mGET /static/assets/archive.svg HTTP/1.1[0m" 304 -
2022-07-08 08:58:42,986 - ERROR: db_connection.getLatestValues(): (2003, "Can't connect to MySQL server on '10.35.232.50:3306' ([Errno 8] nodename nor servname provided, or not known)")
Traceback (most recent call last):
  File "/Library/Python/3.8/site-packages/dbutils/persistent_db.py", line 207, in connection
    con = self.thread.connection
  File "/Library/Developer/CommandLineTools/Library/Frameworks/Python3.framework/Versions/3.8/lib/python3.8/_threading_local.py", line 223, in __getattribute__
    return object.__getattribute__(self, name)
AttributeError: 'local' object has no attribute 'connection'

During handling of the above exception, another exception occurred:

Traceback (most recent call last):
  File "/Library/Python/3.8/site-packages/pymysql/connections.py", line 613, in connect
    sock = socket.create_connection(
  File "/Library/Developer/CommandLineTools/Library/Frameworks/Python3.framework/Versions/3.8/lib/python3.8/socket.py", line 787, in create_connection
    for res in getaddrinfo(host, port, 0, SOCK_STREAM):
  File "/Library/Developer/CommandLineTools/Library/Frameworks/Python3.framework/Versions/3.8/lib/python3.8/socket.py", line 918, in getaddrinfo
    for res in _socket.getaddrinfo(host, port, family, type, proto, flags):
socket.gaierror: [Errno 8] nodename nor servname provided, or not known

During handling of the above exception, another exception occurred:

Traceback (most recent call last):
  File "/Users/temiz/IdeaProjects/temp-observer/app/backend/db_connection.py", line 115, in getLatestValues
    cnx = mysql_connection_pool.connection()
  File "/Library/Python/3.8/site-packages/dbutils/persistent_db.py", line 209, in connection
    con = self.steady_connection()
  File "/Library/Python/3.8/site-packages/dbutils/persistent_db.py", line 194, in steady_connection
    return connect(
  File "/Library/Python/3.8/site-packages/dbutils/steady_db.py", line 135, in connect
    return SteadyDBConnection(
  File "/Library/Python/3.8/site-packages/dbutils/steady_db.py", line 190, in __init__
    self._store(self._create())
  File "/Library/Python/3.8/site-packages/dbutils/steady_db.py", line 208, in _create
    con = self._creator(*self._args, **self._kwargs)
  File "/Library/Python/3.8/site-packages/pymysql/connections.py", line 353, in __init__
    self.connect()
  File "/Library/Python/3.8/site-packages/pymysql/connections.py", line 664, in connect
    raise exc
pymysql.err.OperationalError: (2003, "Can't connect to MySQL server on '10.35.232.50:3306' ([Errno 8] nodename nor servname provided, or not known)")

